Workbook

Sheet Data
A1: Country | B1: Country Code | C1: Series Name | D1: Series Code | E1: 2022 [YR2022]
A2: Afghanistan | B2: AFG | C2: GDP per capita (constant 2015 US$) | D2: NY.GDP.PCAP.KD | E2: 377.66563
A3: Afghanistan | B3: AFG | C3: Life expectancy at birth, total (years) | D3: SP.DYN.LE00.IN | E3: 65.617
A4: Afghanistan | B4: AFG | C4: Government expenditure on education, total (% of GDP) | D4: SE.XPD.TOTL.GD.ZS | E4: ..
A5: Afghanistan | B5: AFG | C5: Political Stability and Absence of Violence/Terrorism: Estimate | D5: PV.EST | E5: -2.544956
A6: Afghanistan | B6: AFG | C6: Unemployment, total (% of total labor force) (modeled ILO estimate) | D6: SL.UEM.TOTL.ZS | E6: 14.1
A7: Africa Eastern and Southern | B7: AFE | C7: GDP per capita (constant 2015 US$) | D7: NY.GDP.PCAP.KD | E7: 1440.4304
A8: Africa Eastern and Southern | B8: AFE | C8: Life expectancy at birth, total (years) | D8: SP.DYN.LE00.IN | E8: 64.48702
A9: Africa Eastern and Southern | B9: AFE | C9: Government expenditure on education, total (% of GDP) | D9: SE.XPD.TOTL.GD.ZS | E9: 3.697668
A10: Africa Eastern and Southern | B10: AFE | C10: Political Stability and Absence of Violence/Terrorism: Estimate | D10: PV.EST | E10: ..
A11: Africa Eastern and Southern | B11: AFE | C11: Unemployment, total (% of total labor force) (modeled ILO estimate) | D11: SL.UEM.TOTL.ZS | E11: 7.9852023
A12: Africa Western and Central | B12: AFW | C12: GDP per capita (constant 2015 US$) | D12: NY.GDP.PCAP.KD | E12: 1757.4566
A13: Africa Western and Central | B13: AFW | C13: Life expectancy at birth, total (years) | D13: SP.DYN.LE00.IN | E13: 57.987813
A14: Africa Western and Central | B14: AFW | C14: Government expenditure on education, total (% of GDP) | D14: SE.XPD.TOTL.GD.ZS | E14: 2.8916874
A15: Africa Western and Central | B15: AFW | C15: Political Stability and Absence of Violence/Terrorism: Estimate | D15: PV.EST | E15: ..
A16: Africa Western and Central | B16: AFW | C16: Unemployment, total (% of total labor force) (modeled ILO estimate) | D16: SL.UEM.TOTL.ZS | E16: 3.6585732
A17: Albania | B17: ALB | C17: GDP per capita (constant 2015 US$) | D17: NY.GDP.PCAP.KD | E17: 5867.651
A18: Albania | B18: ALB | C18: Life expectancy at birth, total (years) | D18: SP.DYN.LE00.IN | E18: 78.769
A19: Albania | B19: ALB | C19: Government expenditure on education, total (% of GDP) | D19: SE.XPD.TOTL.GD.ZS | E19: 2.7297699
A20: Albania | B20: ALB | C20: Political Stability and Absence of Violence/Terrorism: Estimate | D20: PV.EST | E20: 0.10626131
A21: Albania | B21: ALB | C21: Unemployment, total (% of total labor force) (modeled ILO estimate) | D21: SL.UEM.TOTL.ZS | E21: 10.137
A22: Algeria | B22: DZA | C22: GDP per capita (constant 2015 US$) | D22: NY.GDP.PCAP.KD | E22: 4544.4669
A23: Algeria | B23: DZA | C23: Life expectancy at birth, total (years) | D23: SP.DYN.LE00.IN | E23: 76.129
A24: Algeria | B24: DZA | C24: Government expenditure on education, total (% of GDP) | D24: SE.XPD.TOTL.GD.ZS | E24: 4.7492467
A25: Algeria | B25: DZA | C25: Political Stability and Absence of Violence/Terrorism: Estimate | D25: PV.EST | E25: -0.65065235
A26: Algeria | B26: DZA | C26: Unemployment, total (% of total labor force) (modeled ILO estimate) | D26: SL.UEM.TOTL.ZS | E26: 12.346
A27: American Samoa | B27: ASM | C27: GDP per capita (constant 2015 US$) | D27: NY.GDP.PCAP.KD | E27: 13709.097
A28: American Samoa | B28: ASM | C28: Life expectancy at birth, total (years) | D28: SP.DYN.LE00.IN | E28: 72.752
A29: American Samoa | B29: ASM | C29: Government expenditure on education, total (% of GDP) | D29: SE.XPD.TOTL.GD.ZS | E29: ..
A30: American Samoa | B30: ASM | C30: Political Stability and Absence of Violence/Terrorism: Estimate | D30: PV.EST | E30: 1.123174
A31: American Samoa | B31: ASM | C31: Unemployment, total (% of total labor force) (modeled ILO estimate) | D31: SL.UEM.TOTL.ZS | E31: ..
A32: Andorra | B32: AND | C32: GDP per capita (constant 2015 US$) | D32: NY.GDP.PCAP.KD | E32: 39780.415
A33: Andorra | B33: AND | C33: Life expectancy at birth, total (years) | D33: SP.DYN.LE00.IN | E33: 84.016
A34: Andorra | B34: AND | C34: Government expenditure on education, total (% of GDP) | D34: SE.XPD.TOTL.GD.ZS | E34: 2.64728
A35: Andorra | B35: AND | C35: Political Stability and Absence of Violence/Terrorism: Estimate | D35: PV.EST | E35: 1.5859884
A36: Andorra | B36: AND | C36: Unemployment, total (% of total labor force) (modeled ILO estimate) | D36: SL.UEM.TOTL.ZS | E36: ..
A37: Angola | B37: AGO | C37: GDP per capita (constant 2015 US$) | D37: NY.GDP.PCAP.KD | E37: 2860.9025
A38: Angola | B38: AGO | C38: Life expectancy at birth, total (years) | D38: SP.DYN.LE00.IN | E38: 64.246
A39: Angola | B39: AGO | C39: Government expenditure on education, total (% of GDP) | D39: SE.XPD.TOTL.GD.ZS | E39: 2.385359
A40: Angola | B40: AGO | C40: Political Stability and Absence of Violence/Terrorism: Estimate | D40: PV.EST | E40: -0.63010854
...

Sheet GDPpercapita
A1: Country | B1: GDP per capita
A2: Afghanistan | B2: 377.66563
A3: Africa Eastern and Southern | B3: 1440.4304
A4: Africa Western and Central | B4: 1757.4566
A5: Albania | B5: 5867.651
A6: Algeria | B6: 4544.4669
A7: American Samoa | B7: 13709.097
A8: Andorra | B8: 39780.415
A9: Angola | B9: 2860.9025
A10: Antigua and Barbuda | B10: 17456.872
A11: Arab World | B11: 6351.5718
A12: Argentina | B12: 13276.823
A13: Armenia | B13: 4791.0048
... A31: Brazil | B31: 9032.0838
A32: British Virgin Islands | B32: ..
A33: Brunei Darussalam | B33: 28549.176
A34: Bulgaria | B34: 9597.868
A35: Burkina Faso | B35: 740.30632
A36: Burundi | B36: 263.58755
A37: Cabo Verde | B37: 3997.7676
A38: Cambodia | B38: 2011.2743
A39: Cameroon | B39: 1458.6618
A40: Canada | B40: 45677.687
A41: Caribbean small states | B41: 15207.584
A42: Cayman Islands | B42: 80029.032
A43: Central African Republic | B43: 398.9154
A44: Central Europe and the Baltics | B44: 16397.258
... A71: Equatorial Guinea | B71: 5524.2431
A72: Eritrea | B72: ..
A73: Estonia | B73: 21023.299
A74: Eswatini | B74: 3695.6496
A75: Ethiopia | B75: 811.17773
A76: Euro area | B76: 38051.045
A77: Europe & Central Asia | B77: 25418.861
A78: Europe & Central Asia (excluding high income) | B78: 7898.449
A79: Europe & Central Asia (IDA & IBRD countries) | B79: 9668.4362
A80: European Union | B80: 34605.175
A81: Faroe Islands | B81: 57775.076
A82: Fiji | B82: 5291.5169
A83: Finland | B83: 46016.149
...

Sheet LifeExpectancy
A1: Country | B1: Life Expectancy
A2: Afghanistan | B2: 65.617
A3: Africa Eastern and Southern | B3: 64.48702
A4: Africa Western and Central | B4: 57.987813
A5: Albania | B5: 78.769
A6: Algeria | B6: 76.129
A7: American Samoa | B7: 72.752
A8: Andorra | B8: 84.016
A9: Angola | B9: 64.246
A10: Antigua and Barbuda | B10: 77.483
A11: Arab World | B11: 71.876096
A12: Argentina | B12: 75.806
A13: Armenia | B13: 74.765854
... A184: Norway | B184: 82.509756
A185: Not classified | B185: ..
A186: OECD members | B186: 79.521255
A187: Oman | B187: 77.911
A188: Other small states | B188: 72.904925
A189: Pacific island small states | B189: 69.100435
A190: Pakistan | B190: 67.417
A191: Palau | B191: 68.922
A192: Panama | B192: 79.324
A193: Papua New Guinea | B193: 65.274
A194: Paraguay | B194: 72.319
A195: Peru | B195: 76.834
A196: Philippines | B196: 69.472
A197: Poland | B197: 77.156098
... A267: Zimbabwe | B267: 62.36

Sheet FinalData
A1: Clean Country | B1: Happiness | C1: GDP per capita | D1: Life Expectancy
A2: Finland | B2: 7.821 | C2: {=IFERROR(XLOOKUP(A2, GDPpercapita!A:A, GDPpercapita!B:B), "")} -> 46016.149 | D2: {=IFERROR(XLOOKUP(A2, LifeExpectancy!A:A, LifeExpectancy!B:B), "")} -> 81.187805
A3: Denmark | B3: 7.636 | C3: {=IFERROR(XLOOKUP(A3, GDPpercapita!A:A, GDPpercapita!B:B), "")} -> 59108.745 | D3: {=IFERROR(XLOOKUP(A3, LifeExpectancy!A:A, LifeExpectancy!B:B), "")} -> 81.304878
A4: Iceland | B4: 7.557 | C4: {=IFERROR(XLOOKUP(A4, GDPpercapita!A:A, GDPpercapita!B:B), "")} -> 57606.876 | D4: {=IFERROR(XLOOKUP(A4, LifeExpectancy!A:A, LifeExpectancy!B:B), "")} -> 82.119512
A5: Switzerland | B5: 7.512 | C5: {=IFERROR(XLOOKUP(A5, GDPpercapita!A:A, GDPpercapita!B:B), "")} -> 90605.019 | D5: {=IFERROR(XLOOKUP(A5, LifeExpectancy!A:A, LifeExpectancy!B:B), "")} -> 83.604878
A6: Netherlands | B6: 7.415 | C6: {=IFERROR(XLOOKUP(A6, GDPpercapita!A:A, GDPpercapita!B:B), "")} -> 51777.543 | D6: {=IFERROR(XLOOKUP(A6, LifeExpectancy!A:A, LifeExpectancy!B:B), "")} -> 81.614634
A7: Luxembourg | B7: 7.404 | C7: {=IFERROR(XLOOKUP(A7, GDPpercapita!A:A, GDPpercapita!B:B), "")} -> 107467.19 | D7: {=IFERROR(XLOOKUP(A7, LifeExpectancy!A:A, LifeExpectancy!B:B), "")} -> 82.946341
A8: Sweden | B8: 7.384 | C8: {=IFERROR(XLOOKUP(A8, GDPpercapita!A:A, GDPpercapita!B:B), "")} -> 54304.188 | D8: {=IFERROR(XLOOKUP(A8, LifeExpectancy!A:A, LifeExpectancy!B:B), "")} -> 83.058537
A9: Norway | B9: 7.365 | C9: {=IFERROR(XLOOKUP(A9, GDPpercapita!A:A, GDPpercapita!B:B), "")} -> 79620.164 | D9: {=IFERROR(XLOOKUP(A9, LifeExpectancy!A:A, LifeExpectancy!B:B), "")} -> 82.509756
A10: Israel | B10: 7.364 | C10: {=IFERROR(XLOOKUP(A10, GDPpercapita!A:A, GDPpercapita!B:B), "")} -> 42516.389 | D10: {=IFERROR(XLOOKUP(A10, LifeExpectancy!A:A, LifeExpectancy!B:B), "")} -> 82.7
A11: New Zealand | B11: 7.2 | C11: {=IFERROR(XLOOKUP(A11, GDPpercapita!A:A, GDPpercapita!B:B), "")} -> 42965.275 | D11: {=IFERROR(XLOOKUP(A11, LifeExpectancy!A:A, LifeExpectancy!B:B), "")} -> 81.958537
A12: Austria | B12: 7.163 | C12: {=IFERROR(XLOOKUP(A12, GDPpercapita!A:A, GDPpercapita!B:B), "")} -> 47332.424 | D12: {=IFERROR(XLOOKUP(A12, LifeExpectancy!A:A, LifeExpectancy!B:B), "")} -> 81.295122
A13: Australia | B13: 7.162 | C13: {=IFERROR(XLOOKUP(A13, GDPpercapita!A:A, GDPpercapita!B:B), "")} -> 61200.459 | D13: {=IFERROR(XLOOKUP(A13, LifeExpectancy!A:A, LifeExpectancy!B:B), "")} -> 83.2
... A147: Afghanistan | B147: 2.404 | C147: {=IFERROR(XLOOKUP(A147, GDPpercapita!A:A, GDPpercapita!B:B), "")} -> 377.66563 | D147: {=IFERROR(XLOOKUP(A147, LifeExpectancy!A:A, LifeExpectancy!B:B), "")} -> 65.617
C148: {=IFERROR(XLOOKUP(A148, GDPpercapita!A:A, GDPpercapita!B:B), "")} | D148: {=IFERROR(XLOOKUP(A148, LifeExpectancy!A:A, LifeExpectancy!B:B), "")}

Sheet Series - Metadata
A1: Code | B1: License Type | C1: Indicator Name | D1: Short definition | E1: Long definition | F1: Source | G1: Topic | H1: Dataset | I1: Unit of measure | J1: Periodicity | K1: Reference period | L1: Aggregation method | M1: Statistical concept and methodology | N1: Development relevance | O1: Limitations and exceptions | P1: Other notes | Q1: License URL
A2: NY.GDP.PCAP.KD | B2: CC BY-4.0 | C2: GDP per capita (constant 2015 US$) | D2: Gross domestic product is the total income earned through the production of goods and services in an economic territory during an accounting period. It can be measured in three different ways: using either the expenditure approach, the income approach, or the production approach. The core indicator has been divided by the general population to achieve a per capita estimate.This indicator is expressed in constant prices, meaning the series has been adjusted to account for price changes over time. The reference year for this adjustment is 2015. This indicator is expressed in United States dollars. | E2: Gross domestic product is the total income earned through the production of goods and services in an economic territory during an accounting period. It can be measured in three different ways: using either the expenditure approach, the income approach, or the production approach. The core indicator has been divided by the general population to achieve a per capita estimate.This indicator is expressed in constant prices, meaning the series has been adjusted to account for price changes over time. The reference year for this adjustment is 2015. This indicator is expressed in United States dollars. | F2: Country official statistics, National Statistical Organizations and/or Central Banks; National Accounts data files, Organisation for Economic Co-operation and Development (OECD); Staff estimates, World Bank (WB) | G2: Economic Policy & Debt: National accounts: US$ at constant 2015 prices: Aggregate indicators | H2: WB_WDI | I2: constant 2015 US$ | J2: Annual | K2: 1960-2024 | L2: Weighted average | M2: Methodology: National accounts are compiled in accordance with international standards: System of National Accounts, 2008 or 1993 versions. Specific information on how countries compile their national accounts can be found on the IMF website: https://dsbb.imf.org/ Per capita estimates are divided by the total population. Statistical concept(s): The conceptual elements of the SNA (System of National Accounts) measure what takes place in the economy, between which agents, and for what purpose. At the heart of the SNA is the production of goods and services. These may be used for consumption in the period to which the accounts relate or may be accumulated for use in a later period. In simple terms, the amount of value added generated by production represents GDP. The income corresponding to GDP is distributed to the various agents or groups of agents as income and it is the process of distributing and redistributing income that allows one agent to consume the goods and services produced by another agent or to acquire goods and services for later consumption. The way in which the SNA captures this pattern of economic flows is to identify the activities concerned by recognizing the institutional units in the economy and by specifying the structure of accounts capturing the transactions relevant to one stage or another of the process by which goods and services are produced and ultimately consumed. | N2: This indicator is related to the national accounts, which are critical for understanding and managing a country's economy. They provide a framework for the analysis of economic performance. National accounts are the basis for estimating the Gross Domestic Product (GDP) and Gross National Income (GNI), which are the most widely used indicator of economic performance. They are essential for government policymakers, providing the data needed to design and assess fiscal and monetary policies; and are also used by businesses and investors to assess the economic climate and make investment decisions. NAS enable comparison between economies, which is crucial for international trade, investment decisions, and economic competitiveness. More specifically, this indicator is related to national accounts aggregates. Gross Domestic Product (GDP), Gross National Income (GNI), and other aggregates provide a snapshot of the size and health of an economy by measuring the total economic activity within a country. They can thus be used by policymakers to design and implement economic policies, as they reflect the overall economic performance and can indicate the need for intervention in certain areas. Aggregates also allow for comparisons between different economies, which can be useful for trade negotiations, investment decisions, and economic benchmarking. By examining aggregates over time, economists and analysts can identify trends, cycles, and potential areas of concern within an economy, and investors can use national accounts aggregates to assess the potential risks and returns of investing in a particular country. Overall, national accounts aggregates are fundamental tools for economic analysis, policy formulation, and decision-making at both the national and international levels. | Q2: https://datacatalog.worldbank.org/public-licenses#cc-by
A3: SP.DYN.LE00.IN | B3: CC BY-4.0 | C3: Life expectancy at birth, total (years) | D3: Life expectancy at birth indicates the number of years a newborn infant would live if prevailing patterns of mortality at the time of its birth were to stay the same throughout its life. | E3: Life expectancy at birth indicates the number of years a newborn infant would live if prevailing patterns of mortality at the time of its birth were to stay the same throughout its life. | F3: World Population Prospects, United Nations (UN), uri: UN Population Division; Statistical databases and publications from national statistical offices, National statistical offices, note: Derived from male and female life expectancy at birth from sources such as statistical databases and publications from national statistical offices.; Demographic Statistics, Eurostat (ESTAT), note: Derived from male and female life expectancy at birth from sources such as Eurostat: Demographic Statistics. | G3: Health: Mortality | H3: WB_WDI | I3: Years | J3: Annual | K3: 1960-2023 | L3: Weighted average | M3: Methodology: Life expectancy at birth is derived from life tables and is based on sex- and age-specific death rates, or derived from male and female life expectancy at birth. Statistical concept(s): Life expectancy at birth used here is the average number of years a newborn is expected to live if mortality patterns at the time of its birth remain constant in the future. It reflects the overall mortality level of a population, and summarizes the mortality pattern that prevails across all age groups in a given year. It is calculated in a period life table which provides a snapshot of a population's mortality pattern at a given time. It therefore does not reflect the mortality pattern that a person actually experiences during his/her life, which can be calculated in a cohort life table. High mortality in young age groups significantly lowers the life expectancy at birth. But if a person survives his/her childhood of high mortality, he/she may live much longer. For example, in a population with a life expectancy at birth of 50, there may be few people dying at age 50. The life expectancy at birth may be low due to the high childhood mortality so that once a person survives his/her childhood, he/she may live much longer than 50 years. | N3: Mortality rates for different age groups (infants, children, and adults) and overall mortality indicators (life expectancy at birth or survival to a given age) are important indicators of health status in a country. Because data on the incidence and prevalence of diseases are frequently unavailable, mortality rates are often used to identify vulnerable populations. And they are among the indicators most frequently used to compare socioeconomic development across countries. | O3: Annual data series from United Nations Population Division's World Population Prospects are interpolated data from 5-year period data. Therefore they may not reflect real events as much as observed data. | Q3: https://datacatalog.worldbank.org/public-licenses#cc-by
A4: SE.XPD.TOTL.GD.ZS | B4: CC BY-4.0 | C4: Government expenditure on education, total (% of GDP) | D4: General government expenditure on education (current, capital, and transfers) is expressed as a percentage of GDP. It includes expenditure funded by transfers from international sources to government. General government usually refers to local, regional and central governments. | E4: General government expenditure on education (current, capital, and transfers) is expressed as a percentage of GDP. It includes expenditure funded by transfers from international sources to government. General government usually refers to local, regional and central governments. | F4: Data API, UN Educational, Scientific and Cultural Organization (UNESCO), uri: https://databrowser.uis.unesco.org/resources, note: The data are obtained through the UIS API. Detailed documentation is available at: https://api.uis.unesco.org/api/public/documentation/, publisher: UNESCO Institute for Statistics (UIS), date accessed: 2025-09-22, date published: 2025-09 | G4: Education: Inputs | H4: WB_WDI | I4: % of GDP | J4: Annual | K4: 1970-2024 | L4: Median | M4: Methodology: Government expenditure on education, total (% of GDP) is calculated by dividing total government expenditure for all levels of education by the GDP, and multiplying by 100. Aggregate data are based on World Bank estimates. Information pertaining to educational expenditures is sourced from national governments, which provide the data in response to the annual survey conducted by the UNESCO Institute for Statistics (UIS) or through the joint UNESCO-OECD-Eurostat (UOE) data collection initiative. The responses to the questionnaire regarding educational spending are typically derived from the annual financial statements issued by either the Ministry of Finance or the Ministry of Education, or from the national accounts maintained by the National Statistical Office. Additionally, data concerning GDP and overall government expenditure are accessible via the IMF’s World Economic Outlook database, which is updated annually. Statistical concept(s): Generally, elevated levels of the indicator suggest that a government places a high priority on educational policy. Values ranging from 4% to 6% are indicative of a country achieving the benchmark set forth by the Education 2030 Framework for Action (https://uis.unesco.org/sites/default/files/documents/education-2030-incheon-framework-for-action-implementation-of-sdg4-2016-en_2.pdf). Educational expenditure encompasses spending on fundamental educational goods and services, including teaching personnel, school infrastructure, textbooks, and instructional materials, as well as on ancillary educational goods and services such as support services, general administration, and other related activities. Funding for education may originate from public sources, encompassing all government ministries and agencies that finance or support educational programs within the country, as well as from international and private sources, such as household contributions. | N4: Investment in education acts as a driving force for economic growth, enhances productivity, and promotes the betterment of individual and collective welfare. This indicator evaluates the extent to which a government prioritizes education in relation to its overall economic prosperity. | O4: Data may refer to spending by the ministry of education only (excluding spending on educational activities by other ministries). | Q4: https://datacatalog.worldbank.org/public-licenses#cc-by
A5: PV.EST | B5: CC BY-4.0 | C5: Political Stability and Absence of Violence/Terrorism: Estimate | D5: The Worldwide Governance Indicators (WGI) are a research dataset summarizing the views on the quality of governance provided by a large number of enterprise, citizen and expert survey respondents in industrial and developing countries. Governance consists of the traditions and institutions by which authority in a country is exercised. This includes the process by which governments are selected, monitored and replaced; the capacity of the government to effectively formulate and implement sound policies; and the respect of citizens and the state for the institutions that govern economic and social interactions among them. The WGI measures six dimensions of governance: Voice and Accountability, Political Stability and Absence of Violence/Terrorism, Government Effectiveness, Regulatory Quality, Rule of Law, and Control of Corruption. Political Stability and Absence of Violence/Terrorism measures perceptions of the likelihood of political instability and/or politically-motivated violence, including terrorism. Estimate gives the country's score on the aggregate indicator, in units of a standard normal distribution, i.e. ranging from approximately -2.5 to 2.5. | E5: The Worldwide Governance Indicators (WGI) are a research dataset summarizing the views on the quality of governance provided by a large number of enterprise, citizen and expert survey respondents in industrial and developing countries. Governance consists of the traditions and institutions by which authority in a country is exercised. This includes the process by which governments are selected, monitored and replaced; the capacity of the government to effectively formulate and implement sound policies; and the respect of citizens and the state for the institutions that govern economic and social interactions among them. The WGI measures six dimensions of governance: Voice and Accountability, Political Stability and Absence of Violence/Terrorism, Government Effectiveness, Regulatory Quality, Rule of Law, and Control of Corruption. Political Stability and Absence of Violence/Terrorism measures perceptions of the likelihood of political instability and/or politically-motivated violence, including terrorism. Estimate gives the country's score on the aggregate indicator, in units of a standard normal distribution, i.e. ranging from approximately -2.5 to 2.5. | F5: Worldwide Governance Indicators, World Bank (WB), uri: www.govindicators.org | G5: Public Sector: Policy & institutions | H5: WB_WDI | I5: Units of a standard normal distribution (between -2.5 and 2.5, approximately) | J5: Annual | K5: 1996-2023 | M5: Methodology: The WGI are composite governance indicators based on over 30 underlying data sources. These data sources are rescaled and combined to create the six aggregate indicators using a statistical methodology known as an Unobserved Components Model (UCM). A key feature of the methodology is that it generates margins of error for each governance estimate. These margins of error need to be taken into account when making comparisons across countries and over time. Each of the six aggregate WGI measures are constructed by averaging together data from the underlying sources that correspond to the concept of governance being measured. This is done in the three steps: STEP 1: Assigning data from individual sources to the six aggregate indicators. Individual questions from the underlying data sources are assigned to each of the six aggregate indicators. For example, a firm survey question on the regulatory environment would be assigned to Regulatory Quality, or a measure of press freedom would be assigned to Voice and Accountability. The individual variables used in the WGI and how they are assigned to the six aggregate indicators, can be found on the WGI website [https://www.worldbank.org/en/publication/worldwide-governance-indicators]. Note that not all of the data sources cover all countries, and so the aggregate governance scores are based on different sets of underlying data for different countries. STEP 2: Rescaling of the individual source data to run from 0 to 1. The questions from the individual data sources are first rescaled to range from 0 to 1, with higher values corresponding to better outcomes. If, for example, a survey question asks for responses on a scale from a minimum of 1 to a maximum of 4, we rescale a score of 2 as (2-min)/(max-min)=(2-1)/3=0.33. When an individual data source provides more than one question relating to a particular dimension of governance, the rescaled scores are averaged together. The 0-1 rescaled data from the individual sources are available interactively through the WGI website [https://www.worldbank.org/en/publication/worldwide-governance-indicators/interactive-data-access] and in the data files for each individual source [https://www.worldbank.org/en/publication/worldwide-governance-indicators/documentation#2]. Although nominally in the same 0-1 units, this rescaled data is not necessarily comparable across sources. For example, one data source might use a 0-10 scale but in practice most scores are clustered between 6 and 10, while another data source might also use a 0-10 scale but have responses spread out over the entire range. While the max-min rescaling above does not correct for this source of non-comparability, the procedure used to construct the aggregate indicators does (see below). STEP 3: Using an Unobserved Components Model (UCM) to construct a weighted average of the individual indicators for each source. A statistical tool known as an Unobserved Components Model (UCM) is used to make the 0-1 rescaled data comparable across sources, and then to construct a weighted average of the data from each source for each country. The UCM assumes that the observed data from each source are a linear function of the unobserved level of governance, plus an error term. This linear function is different for different data sources, and so corrects for the remaining non-comparability of units of the rescaled data noted above. The resulting estimates of governance are a weighted average of the data from each source, with weights reflecting the pattern of correlation among data sources. The weights applied to the component indicators. | N5: Good governance is essential for development. It helps countries improve economic growth, build human capital, and strengthen social cohesion. Empirical evidence shows a strong causal relationship between better governance and better development outcomes. The Worldwide Governance Indicators (WGI) are designed to help researchers and analysts assess broad patterns in perceptions of governance across countries and over time. The WGI cover over 200 countries and territories, measuring six dimensions of governance starting in 1996: Voice and Accountability, Political Stability and Absence of Violence/Terrorism, Government Effectiveness, Regulatory Quality, Rule of Law, and Control of Corruption. The aggregate indicators are based on several hundred individual underlying variables, taken from a wide variety of existing data sources. The data reflect the views on governance of survey respondents and public, private, and NGO sector experts worldwide. | O5: The six composite WGI measures are useful as a tool for broad cross-country comparisons and for evaluating broad trends over time. However, they are often too blunt a tool to be useful in formulating specific governance reforms in particular country contexts. Such reforms, and evaluation of their progress, need to be informed by much more detailed and country-specific diagnostic data that can identify the relevant constraints on governance in particular country circumstances. The WGI are complementary to a large number of other efforts to construct more detailed measures of governance, often just for a single country. Users are also encouraged to consult the disaggregated individual indicators underlying the composite WGI scores to gain more insights into the particular areas of strengths and weaknesses identified by the data. The WGI do not reflect the official views of the Natural Resource Governance Institute, the Brookings Institution, the World Bank, its Executive Directors, or the countries they represent. The WGI are not used by the World Bank Group to allocate resources. | P5: The UCM assigns greater weight to data sources that tend to be more strongly correlated with each other. While this weighting improves the statistical precision of the aggregate indicators, it typically does not affect very much the ranking of countries on the aggregate indicators. The composite measures of governance generated by the UCM are in units of a standard normal distribution, with mean zero, standard deviation of one, and running from approximately -2.5 to 2.5, with higher values corresponding to better governance. The data is also reported in percentile rank terms, ranging from 0 (lowest rank) to 100 (highest rank). Statistical concept(s): The six aggregate indicators are reported in two ways: (1) in their standard normal units, ranging from approximately -2.5 to 2.5, and (2) in percentile rank terms from 0 to 100, with higher values corresponding to better outcomes. A key feature of the WGI is that all country scores are accompanied by standard errors. These standard errors reflect the number of sources available for a country and the extent to which these sources agree with each other (with more sources and more agreement leading to smaller standard errors). These standard errors reflect the reality that governance is difficult to measure using any kind of data. In most measures of governance or the investment climate they are however left implicit or ignored altogether. | Q5: https://datacatalog.worldbank.org/public-licenses#cc-by
A6: SL.UEM.TOTL.ZS | B6: CC BY-4.0 | C6: Unemployment, total (% of total labor force) (modeled ILO estimate) | D6: Unemployment refers to the share of the labor force that is without work but available for and seeking employment. | E6: Unemployment refers to the share of the labor force that is without work but available for and seeking employment. | F6: ILO Modelled Estimates database (ILOEST), International Labour Organization (ILO), uri: https://ilostat.ilo.org/data/bulk/, publisher: ILOSTAT, type: external database, date accessed: January 07, 2025. | G6: Social Protection & Labor: Unemployment | H6: WB_WDI | I6: % of total labor force | J6: Annual | K6: 1991-2024 | L6: Weighted average | M6: Methodology: The unemployment rate is calculated by expressing the number of unemployed persons as a percentage of the total number of persons in the labor force. The labor force (formerly known as the economically active population) is the sum of the number of persons employed and the number of persons unemployed. The series is part of the "ILO modeled estimates database," including nationally reported observations and imputed data for countries with missing data, primarily to capture regional and global trends with consistent country coverage. Country-reported microdata is based mainly on nationally representative labor force surveys, with other sources (e.g., household surveys and population censuses) considering differences in the data source, the scope of coverage, methodology, and other country-specific factors. Country analysis requires caution where limited nationally reported data are available. A series of models are also applied to impute missing observations and make projections. However, imputed observations are not based on national data, are subject to high uncertainty, and should not be used for country comparisons or rankings. For more information: https://ilostat.ilo.org/resources/concepts-and-definitions/ilo-modelled-estimates/ Statistical concept(s): The unemployed comprise all persons of working age who were: a) without work during the reference period, i.e. were not in paid employment or self-employment; b) currently available for work, i.e. were available for paid employment or self-employment during the reference period; and c) seeking work, i.e. had taken specific steps in a specified recent period to seek paid employment or self-employment. Future starters, that is, persons who did not look for work but have a future labor market stake (made arrangements for a future job start) are also counted as unemployed, as are participants in skills training or retraining schemes within employment promotion programs, who on that basis, were “not in employment”, not “currently available” and did not “seek employment” because they had a job offer to start within a short subsequent period generally not greater than three months. The unemployed also include persons “not in employment” who carried out activities to migrate abroad in order to work for pay or profit but who were still waiting for the opportunity to leave. Employment comprises all persons of working age who during a specified brief period, such as one week or one day, were in the following categories: a) paid employment (whether at work or with a job but not at work); or b) self-employment (whether at work or with an enterprise but not at work). The working-age population is the population above the legal working age, but for statistical purposes it comprises all persons above a specified minimum age threshold for which an inquiry on economic activity is made. To promote international comparability, the working-age population is often defined as all persons aged 15 and older, but this may vary from country to country based on national laws and practices (some countries also apply an upper age limit). | N6: The unemployment rate is a useful measure of the underutilization of the labor supply. It reflects the inability of an economy to generate employment for those persons who want to work but are not doing so, even though they are available for employment and actively seeking work. It is thus seen as an indicator of the efficiency and effectiveness of an economy to absorb its labor force and of the performance of the labor market. Given its usefulness in conveying valuable information on a country’s labor market situation and the fact that it is widely recognized as a headline labor market indicator, it was included as one of the indicators to measure progress towards the achievement of the Sustainable Development Goals (SDG), under Goal 8 (Promote sustained, inclusive and sustainable economic growth, full and productive employment and decent work for all). | O6: While the unemployment rate may be considered the most informative labour market indicator, reflecting the general performance of the labour market and the economy as a whole, it should not be interpreted as a measure of economic hardship or of well-being. When based on the internationally-recommended standards, the unemployment rate simply reflects the proportion of the labour force that does not have a job but is available and actively looking for work. It says nothing about the economic resources of unemployed workers or their family members. Its use should, therefore, be limited to serving as a measurement of the utilization of labour and an indication of the failure to find work. Other measures, including income-related indicators, would be needed to evaluate economic hardship. An additional criticism of the aggregate unemployment measure is that it masks information on the composition of the jobless population and therefore misses out on the particularities of the education level, ethnic origin, socio-economic background, work experience, etc. of the unemployed. Moreover, the unemployment rate says nothing about the type of unemployment – whether it is cyclical and short-term or structural and long-term – which is a critical issue for policy makers in the development of their policy responses, especially given that structural unemployment cannot be addressed by boosting market demand only. | P6: National estimates are also available in the WDI database. Caution should be used when comparing ILO estimates with national estimates. | Q6: https://datacatalog.worldbank.org/public-licenses#cc-by

Sheet Chart1 Happiness Score vs. GDP 
A3: GDP per capita | B3: Happiness
A4: 377.66563 | B4: 2.404
A5: 438.51626 | B5: 4.339
A6: 560.63576 | B6: 3.75
A7: 566.79796 | B7: 5.003
A8: 596.05889 | B8: 5.048
A9: 638.00518 | B9: 5.122
A10: 740.30632 | B10: 4.67
A11: 811.17773 | B11: 4.241
A12: 861.50801 | B12: 4.112
A13: 862.60213 | B13: 4.251
A14: 877.81784 | B14: 4.479
A15: 933.09406 | B15: 4.603
... A130: 107467.19 | B130: 7.404

Sheet Chart2 Happiness Score vs. Life
A3: Life Expectancy | B3: Happiness
A4: 54.079 | B4: 4.552
A5: 54.528 | B5: 4.251
A6: 56.812 | B6: 3.512
A7: 60.035 | B7: 4.479
A8: 60.398 | B8: 5.003
A9: 60.432 | B9: 4.891
A10: 60.475 | B10: 4.623
A11: 60.7 | B11: 4.67
A12: 61.275 | B12: 3.574
A13: 61.934 | B13: 5.122
A14: 62.29 | B14: 4.112
A15: 62.36 | B15: 2.995
... A130: 83.996341 | B130: 6.039

Sheet Chart3 Top 10 Countries by Happ
A3: Clean Country | B3: Happiness
A4: Denmark | B4: 7.636
A5: Finland | B5: 7.821
A6: Iceland | B6: 7.557
A7: Israel | B7: 7.364
A8: Luxembourg | B8: 7.404
A9: Netherlands | B9: 7.415
A10: New Zealand | B10: 7.2
A11: Norway | B11: 7.365
A12: Sweden | B12: 7.384
A13: Switzerland | B13: 7.512
